<?xml version="1.0"?>
<robot xmlns:xacro="http://www.ros.org/wiki/xacro" >

    <xacro:include filename="$(find agv_lince)/description/robot.trans" />
    <xacro:include filename="$(find agv_lince)/description/robot.gazebo" />

    <!-- MATERIALS -->
    <material name="silver">
        <color rgba="0.700 0.700 0.700 1.000"/>
    </material>


    <!-- BASE LINK -->
    <link name="base_link">

    </link>

    <!-- CHASSIS LINK -->
    <joint name="chassi_joint" type="fixed">
        <origin rpy="0 0 0" xyz="0 0 0"/>
        <parent link="base_link"/>
        <child link="chassi"/>
    </joint>

    <link name="chassi">
        <inertial>
            <origin xyz="0.26852392239431533 0.20950930054137695 0.1415018788660424" rpy="0 0 0"/>
            <mass value="196.71182920620697"/>
            <inertia ixx="4.100554" iyy="6.971657" izz="8.324299" ixy="0.000441" iyz="-0.000438" ixz="0.423937"/>
        </inertial>
        <visual>
            <origin xyz="0 0 0" rpy="0 0 0"/>
            <geometry>
                <mesh filename="file://$(find agv_lince)/meshes/chassi.stl" scale="0.001 0.001 0.001"/>
            </geometry>
            <material name="silver"/>
        </visual>
        <collision>
            <origin xyz="0 0 0" rpy="0 0 0"/>
            <geometry>
                <mesh filename="file://$(find agv_lince)/meshes/chassi.stl" scale="0.001 0.001 0.001"/>
            </geometry>
        </collision>
    </link>

    <!-- Left Caster -->
    <joint name="left_caster_joint" type="fixed">
        <origin xyz="0.5255 0.336269 0.1322" rpy="0 0 0"/>
        <parent link="chassi"/>
        <child link="left_caster"/>
    </joint>

    <link name="left_caster">
        <inertial>
            <origin xyz="0.0002703596792763552 2.5251487542454765e-05 -0.06165617323973693" rpy="0 0 0"/>
            <mass value="5.442426439867197"/>
            <inertia ixx="0.013498" iyy="0.015226" izz="0.00705" ixy="-1e-06" iyz="1e-05" ixz="6.6e-05"/>
        </inertial>
        <visual>
            <origin xyz="-0.5255 -0.336269 -0.1322" rpy="0 0 0"/>
            <geometry>
                <mesh filename="file://$(find agv_lince)/meshes/left_caster_1.stl" scale="0.001 0.001 0.001"/>
            </geometry>
            <material name="silver"/>
        </visual>
        <collision>
            <origin xyz="-0.5255 -0.336269 -0.1322" rpy="0 0 0"/>
            <geometry>
                <mesh filename="file://$(find agv_lince)/meshes/left_caster_1.stl" scale="0.001 0.001 0.001"/>
            </geometry>
        </collision>
    </link>

    <!-- Right Caster -->
    <joint name="right_caster_joint" type="fixed">
        <origin xyz="0.5255 0.075954 0.1322" rpy="0 0 0"/>
        <parent link="chassi"/>
        <child link="right_caster"/>
    </joint>
    
    <link name="right_caster">
        <inertial>
            <origin xyz="0.00027035967927580007 0.00033953726364627235 -0.06165617323973689" rpy="0 0 0"/>
                <mass value="5.442426439867197"/>
            <inertia ixx="0.013498" iyy="0.015226" izz="0.00705" ixy="-1e-06" iyz="1e-05" ixz="6.6e-05"/>
        </inertial>
        <visual>
            <origin xyz="-0.5255 -0.075954 -0.1322" rpy="0 0 0"/>
            <geometry>
                <mesh filename="file://$(find agv_lince)/meshes/right_caster_3.stl" scale="0.001 0.001 0.001"/>
            </geometry>
            <material name="silver"/>
        </visual>
        <collision>
            <origin xyz="-0.5255 -0.075954 -0.1322" rpy="0 0 0"/>
            <geometry>
                <mesh filename="file://$(find agv_lince)/meshes/right_caster_3.stl" scale="0.001 0.001 0.001"/>
            </geometry>
        </collision>
    </link>

    <!-- Left Wheel -->
    <joint name="left_wheel_joint" type="continuous">
        <origin xyz="0.086098 0.414 0.0522" rpy="0 0 0"/>
        <parent link="chassi"/>
        <child link="left_wheel"/>
        <axis xyz="0.0 1.0 0.0"/>
    </joint>

    <link name="left_wheel">
    <inertial>
        <origin xyz="-2.7028745609725124e-07 0.03596400994364629 -6.938893903907228e-18" rpy="0 0 0"/>
        <mass value="11.320743431486168"/>
        <inertia ixx="0.024546" iyy="0.04182" izz="0.024546" ixy="-0.0" iyz="-0.0" ixz="0.0"/>
    </inertial>
    <visual>
        <origin xyz="-0.086098 -0.414 -0.0522" rpy="0 0 0"/>
        <geometry>
            <mesh filename="file://$(find agv_lince)/meshes/left_wheel_1.stl" scale="0.001 0.001 0.001"/>
        </geometry>
        <material name="silver"/>
    </visual>
    <collision>
        <origin xyz="-0.086098 -0.414 -0.0522" rpy="0 0 0"/>
        <geometry>
            <mesh filename="file://$(find agv_lince)/meshes/left_wheel_1.stl" scale="0.001 0.001 0.001"/>
        </geometry>
    </collision>
    </link>

    <!-- Right Wheel -->
    <joint name="right_wheel_joint" type="continuous">
        <origin xyz="0.082222 0.005 0.066" rpy="0 0 0"/>
        <parent link="chassi"/>
        <child link="right_wheel"/>
        <axis xyz="0.0 1.0 0.0"/>
    </joint>

    <link name="right_wheel">
    <inertial>
        <origin xyz="-1.1151555552590953e-07 -0.03596400940058405 0.0" rpy="0 0 0"/>
        <mass value="11.32074361520196"/>
        <inertia ixx="0.024546" iyy="0.04182" izz="0.024546" ixy="-0.0" iyz="-0.0" ixz="0.0"/>
    </inertial>
    <visual>
        <origin xyz="-0.082222 -0.005 -0.066" rpy="0 0 0"/>
        <geometry>
            <mesh filename="file://$(find agv_lince)/meshes/right_wheel_1.stl" scale="0.001 0.001 0.001"/>
        </geometry>
        <material name="silver"/>
    </visual>
    <collision>
        <origin xyz="-0.082222 -0.005 -0.066" rpy="0 0 0"/>
        <geometry>
            <mesh filename="file://$(find agv_lince)/meshes/right_wheel_1.stl" scale="0.001 0.001 0.001"/>
        </geometry>
    </collision>
    </link>

    <!-- Camera -->
    <!-- <joint name="R gido 12" type="fixed">
        <origin xyz="0.65505 0.2095 0.2277" rpy="0 0 0"/>
        <parent link="chassi"/>
        <child link="camera_1"/>
    </joint>

    <link name="camera_1">
        <inertial>
            <origin xyz="-0.006290550800018169 -3.1499090842684874e-05 0.036766020010442935" rpy="0 0 0"/>
            <mass value="3.5762687778267663"/>
            <inertia ixx="0.003848" iyy="0.003414" izz="0.004063" ixy="6e-06" iyz="1e-06" ixz="6.9e-05"/>
        </inertial>
        <visual>
            <origin xyz="-0.65505 -0.2095 -0.2277" rpy="0 0 0"/>
            <geometry>
                <mesh filename="file://$(find agv_lince)/meshes/camera_1.stl" scale="0.001 0.001 0.001"/>
            </geometry>
            <material name="silver"/>
        </visual>
        <collision>
            <origin xyz="-0.65505 -0.2095 -0.2277" rpy="0 0 0"/>
            <geometry>
                <mesh filename="file:/;$(find agv_lince)/meshes/camera_1.stl" scale="0.001 0.001 0.001"/>
            </geometry>
        </collision>
    </link> -->


</robot>